<?xml version="1.0" encoding="UTF-8"?>
<testng-results ignored="0" total="2" passed="0" failed="2" skipped="0">
  <reporter-output>
    <line>
      <![CDATA[capturing screenshot on failure]]>
    </line>
    <line>
      <![CDATA[<a target="_blank" href=C:\Users\ivenugopal\GitWorkSpace\DataDrivenFramework//target//surefire-reports//html//Mon_May_17_22_49_34_IST_2021.jpg>Screenshot</a>]]>
    </line>
    <line>
      <![CDATA[capturing screenshot on failure]]>
    </line>
    <line>
      <![CDATA[<a target="_blank" href=C:\Users\ivenugopal\GitWorkSpace\DataDrivenFramework//target//surefire-reports//html//Mon_May_17_22_49_40_IST_2021.jpg>Screenshot</a>]]>
    </line>
  </reporter-output>
  <suite started-at="2021-05-17T22:49:31 IST" name="DataDrivenBasics" finished-at="2021-05-17T22:49:40 IST" duration-ms="9794">
    <groups>
    </groups>
    <test started-at="2021-05-17T22:49:31 IST" name="LoginTest" finished-at="2021-05-17T22:49:35 IST" duration-ms="4284">
      <class name="com.w2a.testCases.LoginTest">
        <test-method signature="loginAsBankManager()[pri:0, instance:com.w2a.testCases.LoginTest@6d4e5011]" started-at="2021-05-17T22:49:31 IST" name="loginAsBankManager" finished-at="2021-05-17T22:49:34 IST" duration-ms="3277" status="FAIL">
          <exception class="java.lang.AssertionError">
            <message>
              <![CDATA[Failing after  login test)]]>
            </message>
            <full-stacktrace>
              <![CDATA[java.lang.AssertionError: Failing after  login test)
at org.testng.Assert.fail(Assert.java:99)
at com.w2a.testCases.LoginTest.loginAsBankManager(LoginTest.java:29)
at java.base/jdk.internal.reflect.NativeMethodAccessorImpl.invoke0(Native Method)
at java.base/jdk.internal.reflect.NativeMethodAccessorImpl.invoke(NativeMethodAccessorImpl.java:64)
at java.base/jdk.internal.reflect.DelegatingMethodAccessorImpl.invoke(DelegatingMethodAccessorImpl.java:43)
at java.base/java.lang.reflect.Method.invoke(Method.java:564)
at org.testng.internal.MethodInvocationHelper.invokeMethod(MethodInvocationHelper.java:133)
at org.testng.internal.TestInvoker.invokeMethod(TestInvoker.java:598)
at org.testng.internal.TestInvoker.invokeTestMethod(TestInvoker.java:173)
at org.testng.internal.MethodRunner.runInSequence(MethodRunner.java:46)
at org.testng.internal.TestInvoker$MethodInvocationAgent.invoke(TestInvoker.java:824)
at org.testng.internal.TestInvoker.invokeTestMethods(TestInvoker.java:146)
at org.testng.internal.TestMethodWorker.invokeTestMethods(TestMethodWorker.java:146)
at org.testng.internal.TestMethodWorker.run(TestMethodWorker.java:128)
at java.base/java.util.ArrayList.forEach(ArrayList.java:1511)
at org.testng.TestRunner.privateRun(TestRunner.java:794)
at org.testng.TestRunner.run(TestRunner.java:596)
at org.testng.SuiteRunner.runTest(SuiteRunner.java:377)
at org.testng.SuiteRunner.runSequentially(SuiteRunner.java:371)
at org.testng.SuiteRunner.privateRun(SuiteRunner.java:332)
at org.testng.SuiteRunner.run(SuiteRunner.java:276)
at org.testng.SuiteRunnerWorker.runSuite(SuiteRunnerWorker.java:53)
at org.testng.SuiteRunnerWorker.run(SuiteRunnerWorker.java:96)
at org.testng.TestNG.runSuitesSequentially(TestNG.java:1212)
at org.testng.TestNG.runSuitesLocally(TestNG.java:1134)
at org.testng.TestNG.runSuites(TestNG.java:1063)
at org.testng.TestNG.run(TestNG.java:1031)
at org.apache.maven.surefire.testng.TestNGExecutor.run(TestNGExecutor.java:295)
at org.apache.maven.surefire.testng.TestNGXmlTestSuite.execute(TestNGXmlTestSuite.java:84)
at org.apache.maven.surefire.testng.TestNGProvider.invoke(TestNGProvider.java:90)
at org.apache.maven.surefire.booter.ForkedBooter.invokeProviderInSameClassLoader(ForkedBooter.java:203)
at org.apache.maven.surefire.booter.ForkedBooter.runSuitesInProcess(ForkedBooter.java:155)
at org.apache.maven.surefire.booter.ForkedBooter.main(ForkedBooter.java:103)
]]>
            </full-stacktrace>
          </exception> <!-- java.lang.AssertionError -->
          <reporter-output>
            <line>
              <![CDATA[capturing screenshot on failure]]>
            </line>
            <line>
              <![CDATA[<a target="_blank" href=C:\Users\ivenugopal\GitWorkSpace\DataDrivenFramework//target//surefire-reports//html//Mon_May_17_22_49_34_IST_2021.jpg>Screenshot</a>]]>
            </line>
          </reporter-output>
        </test-method> <!-- loginAsBankManager -->
      </class> <!-- com.w2a.testCases.LoginTest -->
    </test> <!-- LoginTest -->
    <test started-at="2021-05-17T22:49:35 IST" name="Add Customer test" finished-at="2021-05-17T22:49:40 IST" duration-ms="5474">
      <class name="com.w2a.testCases.AddingUsersTest">
        <test-method is-config="true" signature="setup()[pri:0, instance:com.w2a.testCases.AddingUsersTest@52af26ee]" started-at="2021-05-17T22:49:21 IST" name="setup" finished-at="2021-05-17T22:49:31 IST" duration-ms="9589" status="PASS">
          <reporter-output>
          </reporter-output>
        </test-method> <!-- setup -->
        <test-method signature="AddUsers(java.lang.String,java.lang.String,java.lang.String,java.lang.String)[pri:0, instance:com.w2a.testCases.AddingUsersTest@52af26ee]" started-at="2021-05-17T22:49:36 IST" name="AddUsers" data-provider="dataGetter" finished-at="2021-05-17T22:49:40 IST" duration-ms="3847" status="FAIL">
          <params>
            <param index="0">
              <value>
                <![CDATA[Venu]]>
              </value>
            </param>
            <param index="1">
              <value>
                <![CDATA[Gopal]]>
              </value>
            </param>
            <param index="2">
              <value>
                <![CDATA[5a00072]]>
              </value>
            </param>
            <param index="3">
              <value>
                <![CDATA[Customer added successfully]]>
              </value>
            </param>
          </params>
          <exception class="java.lang.AssertionError">
            <message>
              <![CDATA[Failing after  Adding user test)]]>
            </message>
            <full-stacktrace>
              <![CDATA[java.lang.AssertionError: Failing after  Adding user test)
at org.testng.Assert.fail(Assert.java:99)
at com.w2a.testCases.AddingUsersTest.AddUsers(AddingUsersTest.java:37)
at java.base/jdk.internal.reflect.NativeMethodAccessorImpl.invoke0(Native Method)
at java.base/jdk.internal.reflect.NativeMethodAccessorImpl.invoke(NativeMethodAccessorImpl.java:64)
at java.base/jdk.internal.reflect.DelegatingMethodAccessorImpl.invoke(DelegatingMethodAccessorImpl.java:43)
at java.base/java.lang.reflect.Method.invoke(Method.java:564)
at org.testng.internal.MethodInvocationHelper.invokeMethod(MethodInvocationHelper.java:133)
at org.testng.internal.TestInvoker.invokeMethod(TestInvoker.java:598)
at org.testng.internal.TestInvoker.invokeTestMethod(TestInvoker.java:173)
at org.testng.internal.MethodRunner.runInSequence(MethodRunner.java:46)
at org.testng.internal.TestInvoker$MethodInvocationAgent.invoke(TestInvoker.java:824)
at org.testng.internal.TestInvoker.invokeTestMethods(TestInvoker.java:146)
at org.testng.internal.TestMethodWorker.invokeTestMethods(TestMethodWorker.java:146)
at org.testng.internal.TestMethodWorker.run(TestMethodWorker.java:128)
at java.base/java.util.ArrayList.forEach(ArrayList.java:1511)
at org.testng.TestRunner.privateRun(TestRunner.java:794)
at org.testng.TestRunner.run(TestRunner.java:596)
at org.testng.SuiteRunner.runTest(SuiteRunner.java:377)
at org.testng.SuiteRunner.runSequentially(SuiteRunner.java:371)
at org.testng.SuiteRunner.privateRun(SuiteRunner.java:332)
at org.testng.SuiteRunner.run(SuiteRunner.java:276)
at org.testng.SuiteRunnerWorker.runSuite(SuiteRunnerWorker.java:53)
at org.testng.SuiteRunnerWorker.run(SuiteRunnerWorker.java:96)
at org.testng.TestNG.runSuitesSequentially(TestNG.java:1212)
at org.testng.TestNG.runSuitesLocally(TestNG.java:1134)
at org.testng.TestNG.runSuites(TestNG.java:1063)
at org.testng.TestNG.run(TestNG.java:1031)
at org.apache.maven.surefire.testng.TestNGExecutor.run(TestNGExecutor.java:295)
at org.apache.maven.surefire.testng.TestNGXmlTestSuite.execute(TestNGXmlTestSuite.java:84)
at org.apache.maven.surefire.testng.TestNGProvider.invoke(TestNGProvider.java:90)
at org.apache.maven.surefire.booter.ForkedBooter.invokeProviderInSameClassLoader(ForkedBooter.java:203)
at org.apache.maven.surefire.booter.ForkedBooter.runSuitesInProcess(ForkedBooter.java:155)
at org.apache.maven.surefire.booter.ForkedBooter.main(ForkedBooter.java:103)
]]>
            </full-stacktrace>
          </exception> <!-- java.lang.AssertionError -->
          <reporter-output>
            <line>
              <![CDATA[capturing screenshot on failure]]>
            </line>
            <line>
              <![CDATA[<a target="_blank" href=C:\Users\ivenugopal\GitWorkSpace\DataDrivenFramework//target//surefire-reports//html//Mon_May_17_22_49_40_IST_2021.jpg>Screenshot</a>]]>
            </line>
          </reporter-output>
        </test-method> <!-- AddUsers -->
        <test-method is-config="true" signature="TearDown()[pri:0, instance:com.w2a.testCases.AddingUsersTest@52af26ee]" started-at="2021-05-17T22:49:40 IST" name="TearDown" finished-at="2021-05-17T22:49:44 IST" duration-ms="4102" status="PASS">
          <reporter-output>
          </reporter-output>
        </test-method> <!-- TearDown -->
      </class> <!-- com.w2a.testCases.AddingUsersTest -->
    </test> <!-- Add Customer test -->
  </suite> <!-- DataDrivenBasics -->
</testng-results>
